Workbook
Name Slicer_Period: #N/A
Name Slicer_Segment: #N/A

Sheet 01_Cover
A1: ROYAL BANK OF CANADA — BANKING FINANCIAL ANALYSIS
A4: Financial Performance, Credit Risk and Capital Adequacy Analysis
A6: Company | B6: Royal Bank of Canada
A7: Ticker | B7: RY
A8: Industry | B8: Banking and Financial Services
A9: Reporting Period | B9: FY2023–FY2025 and Q1 2024–Q2 2026
A10: Reporting Currency | B10: Canadian dollars
A11: Reporting Unit | B11: CAD millions unless otherwise stated
A12: Reporting Framework | B12: IFRS
A13: Prepared By | B13: Neha R K
A14: Project Type | B14: Independent Finance and Accounting Portfolio Project
A15: Project Status | B15: Completed
A16: Data Cutoff | B16: April 30, 2026
A18: Purpose
A19: Evaluate RBC’s profitability, operating efficiency, credit quality, business-segment performance, regulatory capital and liquidity using publicly available annual and quarterly disclosures.
A24: Disclaimer
A25: This independent educational portfolio project is based solely on publicly available information published by Royal Bank of Canada. It is not affiliated with, sponsored by, or endorsed by RBC and does not constitute investment, accounting, tax, legal, or financial advice.
A31: ADVANCED EXCEL REVIEW
A32: Review Sheet 22 for XLOOKUP, LET, IFS, FILTER, SORTBY, RANK.EQ and sparklines. Review Sheet 23 for the normalized Excel Table used as a PivotTable source. Review Sheet 24 for the interactive SUMIFS-driven pivot-style management summary.

Sheet 02_Project_Charter
A1: PROJECT CHARTER
A4: Project Overview
A5: Field | B5: Content
A6: Project Title | B6: Royal Bank of Canada Financial Performance, Credit Risk and Capital Adequacy Analysis
A7: Company | B7: Royal Bank of Canada
A8: Industry | B8: Banking and Financial Services
A9: Project Type | B9: Independent Finance and Accounting Portfolio Project
A10: Analysis Period | B10: FY2023–FY2025 and Q1 2024–Q2 2026
A11: Reporting Currency | B11: Canadian dollars
A12: Reporting Unit | B12: CAD millions unless otherwise stated
A13: Primary Tool | B13: Microsoft Excel
A14: Project Status | B14: Completed
A15: Prepared By | B15: Neha R K
A16: Data Cutoff | B16: April 30, 2026
A18: Project Objective
A19: The objective of this project is to evaluate Royal Bank of Canada’s financial performance, operating efficiency, credit-risk profile, business-segment performance and regulatory capital position using publicly available annual and quarterly disclosures. The project converts complex banking information into a structured Excel model, analytical dashboard and professional financial report.
A24: Business Questions
A25: 1 | B25: Is RBC generating sustainable revenue and earnings growth?
A26: 2 | B26: How are net interest income and non-interest income changing?
A27: 3 | B27: Are operating expenses growing faster or slower than revenue?
A28: 4 | B28: How has return on equity changed?
A29: 5 | B29: Is credit quality strengthening or deteriorating?
A30: 6 | B30: How have provisions for credit losses and impaired loans changed?
A31: 7 | B31: Does RBC maintain strong regulatory capital and liquidity?
A32: 8 | B32: Which business segments contribute most to revenue and net income?
A33: 9 | B33: What strengths and risks are visible in the latest results?
A35: Intended Audience | E35: Project Deliverables
A36: Junior Financial Analyst | E36: Excel financial-analysis model
A37: Financial Reporting Analyst | E37: Banking KPI and ratio analysis
A38: Accounting Analyst | E38: Credit-risk analysis
A39: Banking Analyst | E39: Capital and liquidity analysis
A40: Credit Analyst | E40: Segment-performance analysis
A41: Risk Analyst | E41: Executive dashboard
A42: Finance Operations | E42: Professional financial report
A43: New-Graduate Finance Programs | E43: Methodology and source documentation
A45: ADVANCED EXCEL CAPABILITIES DEMONSTRATED
A46: Feature | B46: Portfolio Evidence
A47: Excel Tables | B47: RBC_Annual_Performance, RBC_Quarterly_Performance, RBC_Segment_Results and RBC_Pivot_Source
A48: XLOOKUP | B48: Interactive KPI retrieval by selected period and metric
A49: LET and IFS | B49: Readable period-comparison logic and metric-aware performance assessment
...

Sheet 03_Source_Register
A1: SOURCE REGISTER
A4: Source ID | B4: File Name | C4: Reporting Period | D4: Document Type | E4: Main Information Used | F4: Format | G4: Status | H4: Page / Table | I4: Source URL | J4: Notes
A5: AR-25 | B5: RBC_2025_Annual_Report.pdf | C5: FY2025 | D5: Audited Annual Report | E5: Annual statements, notes, MD&A and accounting policies | F5: PDF | G5: Validated | I5: https://www.rbc.com/investor-relations/financial-information.html | J5: Used in completed model; detailed source mapping is included in raw-data schedules
A6: SUP-25Q4-PDF | B6: RBC_Q4_2025_Financial_Supplement.pdf | C6: Q4/FY2025 | D6: Financial Supplement | E6: Annual and quarterly financial schedules | F6: PDF | G6: Validated | I6: https://www.rbc.com/investor-relations/financial-information.html | J6: Used in completed model; detailed source mapping is included in raw-data schedules
A7: SUP-25Q4-XLS | B7: RBC_Q4_2025_Financial_Supplement.xlsx | C7: Q4/FY2025 | D7: Financial Supplement | E7: Extractable annual and quarterly data | F7: Excel | G7: Validated | I7: https://www.rbc.com/investor-relations/financial-information.html | J7: Used in completed model; detailed source mapping is included in raw-data schedules
A8: QR-26Q2 | B8: RBC_Q2_2026_Report_to_Shareholders.pdf | C8: Q2 2026 | D8: Interim Report | E8: Latest results, MD&A and statements | F8: PDF | G8: Validated | I8: https://www.rbc.com/investor-relations/financial-information.html | J8: Used in completed model; detailed source mapping is included in raw-data schedules
A9: SUP-26Q2-PDF | B9: RBC_Q2_2026_Financial_Supplement.pdf | C9: Q2 2026 | D9: Financial Supplement | E9: Quarterly trends, segments, credit and capital | F9: PDF | G9: Validated | I9: https://www.rbc.com/investor-relations/financial-information.html | J9: Used in completed model; detailed source mapping is included in raw-data schedules
A10: SUP-26Q2-XLS | B10: RBC_Q2_2026_Financial_Supplement.xlsx | C10: Q2 2026 | D10: Financial Supplement | E10: Extractable quarterly data | F10: Excel | G10: Validated | I10: https://www.rbc.com/investor-relations/financial-information.html | J10: Used in completed model; detailed source mapping is included in raw-data schedules
A11: P3-26Q2-PDF | B11: RBC_Q2_2026_Pillar_3_Disclosure.pdf | C11: Q2 2026 | D11: Regulatory Disclosure | E11: Capital, RWA and risk exposure | F11: PDF | G11: Validated | I11: https://www.rbc.com/investor-relations/financial-information.html | J11: Used in completed model; detailed source mapping is included in raw-data schedules
A12: P3-26Q2-XLS | B12: RBC_Q2_2026_Pillar_3_Quantitative_Tables.xlsx | C12: Q2 2026 | D12: Regulatory Tables | E12: Capital and regulatory-risk data | F12: Excel | G12: Validated | I12: https://www.rbc.com/investor-relations/financial-information.html | J12: Used in completed model; detailed source mapping is included in raw-data schedules
A13: PR-26Q2 | B13: RBC_Q2_2026_Earnings_Release.pdf | C13: Q2 2026 | D13: Earnings Release | E13: Executive financial highlights | F13: PDF | G13: Validated | I13: https://www.rbc.com/investor-relations/financial-information.html | J13: Used in completed model; detailed source mapping is included in raw-data schedules

Sheet 04_Definitions
A1: BANKING DEFINITIONS
A4: Term | B4: Abbreviation | C4: Working Definition | D4: Why It Matters | E4: Primary Source
A5: Net Interest Income | B5: NII | C5: Interest income earned less interest expense | D5: Core banking revenue and sensitivity to rates, loan growth and funding costs | E5: RBC Annual / Quarterly Reports
A6: Non-Interest Income | B6: — | C6: Revenue from fees, trading, insurance and other non-interest activities | D6: Shows diversification beyond lending spreads | E6: RBC Financial Supplement
A7: Provision for Credit Losses | B7: PCL | C7: Expense recognized for expected credit losses | D7: Directly affects earnings and signals expected credit deterioration | E7: RBC Reports and Supplement
A8: Allowance for Credit Losses | B8: ACL | C8: Balance-sheet reserve against expected credit losses | D8: Indicates reserves available to absorb expected loan losses | E8: RBC Reports and Supplement
A9: Gross Impaired Loans | B9: GIL | C9: Loans identified as credit-impaired | D9: Measures the stock of problem loans | E9: RBC Financial Supplement
A10: Common Equity Tier 1 Ratio | B10: CET1 | C10: Highest-quality regulatory capital relative to risk-weighted assets | D10: Key measure of loss-absorbing capital strength | E10: RBC Pillar 3
A11: Risk-Weighted Assets | B11: RWA | C11: Assets weighted according to regulatory risk | D11: Denominator for regulatory capital ratios | E11: RBC Pillar 3
A12: Return on Equity | B12: ROE | C12: Net income available to common shareholders relative to common equity | D12: Measures profitability generated from shareholder capital | E12: RBC Financial Supplement
A13: Efficiency Ratio | B13: — | C13: Non-interest expense divided by total revenue | D13: Lower values generally indicate better operating efficiency | E13: RBC Financial Supplement
A14: Operating Leverage | B14: — | C14: Revenue growth minus expense growth | D14: Shows whether revenue is growing faster than costs | E14: RBC Reports
A15: Liquidity Coverage Ratio | B15: LCR | C15: High-quality liquid assets relative to projected short-term cash outflows | D15: Assesses short-term liquidity resilience | E15: RBC Pillar 3 / Liquidity Disclosure
... A20: Adjusted Results | B20: — | C20: Management-defined results excluding specified items | D20: Useful supplementary view but must not be mixed with reported figures | E20: RBC Reports

Sheet 05_Raw_Annual_Performance
A1: RAW ANNUAL PERFORMANCE
A4: Metric | B4: Unit | C4: FY2023 | D4: FY2024 | E4: FY2025 | F4: Source ID | G4: Page / Table | H4: Source URL | I4: Notes
A5: Net Interest Income | B5: CAD millions | C5: 25129 | D5: 27953 | E5: 33000 | F5: SUP-24Q4-XLS / SUP-25Q4-XLS | G5: Statements of Income – Page 5, annual columns | H5: https://www.rbc.com/investor-relations/financial-information.html | I5: Reported annual result; CAD millions
A6: Non-Interest Income | B6: CAD millions | C6: 26335 | D6: 29391 | E6: 33605 | F6: SUP-24Q4-XLS / SUP-25Q4-XLS | G6: Statements of Income – Page 5, annual columns | H6: https://www.rbc.com/investor-relations/financial-information.html | I6: Reported annual result; CAD millions
A7: Total Revenue | B7: CAD millions | C7: 51464 | D7: 57344 | E7: 66605 | F7: SUP-24Q4-XLS / SUP-25Q4-XLS | G7: Statements of Income – Page 5, annual columns | H7: https://www.rbc.com/investor-relations/financial-information.html | I7: Reported annual result; CAD millions
A8: Provision for Credit Losses | B8: CAD millions | C8: 2468 | D8: 3232 | E8: 4362 | F8: SUP-24Q4-XLS / SUP-25Q4-XLS | G8: Statements of Income – Page 5, annual columns | H8: https://www.rbc.com/investor-relations/financial-information.html | I8: Reported annual result; CAD millions
A9: Non-Interest Expense | B9: CAD millions | C9: 30813 | D9: 34250 | E9: 36592 | F9: SUP-24Q4-XLS / SUP-25Q4-XLS | G9: Statements of Income – Page 5, annual columns | H9: https://www.rbc.com/investor-relations/financial-information.html | I9: Reported annual result; CAD millions
A10: Income Before Income Taxes | B10: CAD millions | C10: 18183 | D10: 19862 | E10: 25651 | F10: SUP-24Q4-XLS / SUP-25Q4-XLS | G10: Statements of Income – Page 5, annual columns | H10: https://www.rbc.com/investor-relations/financial-information.html | I10: Reported annual result; CAD millions
A11: Income Taxes | B11: CAD millions | C11: 3571 | D11: 3622 | E11: 5282 | F11: SUP-24Q4-XLS / SUP-25Q4-XLS | G11: Statements of Income – Page 5, annual columns | H11: https://www.rbc.com/investor-relations/financial-information.html | I11: Reported annual result; CAD millions
A12: Net Income | B12: CAD millions | C12: 14612 | D12: 16240 | E12: 20369 | F12: SUP-24Q4-XLS / SUP-25Q4-XLS | G12: Statements of Income – Page 5, annual columns | H12: https://www.rbc.com/investor-relations/financial-information.html | I12: Reported annual result; CAD millions
A13: Net Income Available to Common Shareholders | B13: CAD millions | C13: 14369 | D13: 15908 | E13: 19868 | F13: SUP-24Q4-XLS / SUP-25Q4-XLS | G13: Statements of Income – Page 5, annual columns | H13: https://www.rbc.com/investor-relations/financial-information.html | I13: Reported annual result; CAD millions
A14: Diluted EPS | B14: CAD per share | C14: 10.32 | D14: 11.25 | E14: 14.07 | F14: SUP-24Q4-XLS / SUP-25Q4-XLS | G14: Financial Highlights – Page 2, annual columns | H14: https://www.rbc.com/investor-relations/financial-information.html | I14: Reported annual result; CAD per common share
A15: ROE | B15: % | C15: 0.143 | D15: 0.144 | E15: 0.163 | F15: SUP-24Q4-XLS / SUP-25Q4-XLS | G15: Financial Highlights – Page 2, annual columns | H15: https://www.rbc.com/investor-relations/financial-information.html | I15: RBC-reported ratio
A16: Efficiency Ratio | B16: % | C16: 0.599 | D16: 0.597 | E16: 0.549 | F16: SUP-24Q4-XLS / SUP-25Q4-XLS | G16: Financial Highlights – Page 2, annual columns | H16: https://www.rbc.com/investor-relations/financial-information.html | I16: RBC-reported ratio
... A19: Effective Tax Rate | B19: % | C19: 0.19639223 | D19: 0.18235827 | E19: 0.2059179 | F19: Model Calculation | G19: Calculated from Statements of Income | H19: https://www.rbc.com/investor-relations/financial-information.html | I19: Formula: Income taxes ÷ Income before tax

Sheet 06_Raw_Quarterly_Performance
A1: RAW QUARTERLY PERFORMANCE
A4: Metric | B4: Unit | C4: Q1 2024 | D4: Q2 2024 | E4: Q3 2024 | F4: Q4 2024 | G4: Q1 2025 | H4: Q2 2025 | I4: Q3 2025 | J4: Q4 2025 | K4: Q1 2026 | L4: Q2 2026 | M4: Source ID | N4: Page / Table | O4: Notes
A5: Net Interest Income | B5: CAD millions | C5: 6332 | D5: 6623 | E5: 7327 | F5: 7671 | G5: 7948 | H5: 8056 | I5: 8351 | J5: 8645 | K5: 8585 | L5: 8506 | M5: SUP-24Q4-XLS / SUP-25Q4-XLS / SUP-26Q2-XLS | N5: Financial Highlights Page 2 / Statements of Income Page 5 | O5: Single-quarter reported values; PPPT and tax rate are model calculations where applicable
A6: Non-Interest Income | B6: CAD millions | C6: 7153 | D6: 7531 | E6: 7304 | F6: 7403 | G6: 8791 | H6: 7616 | I6: 8634 | J6: 8564 | K6: 9375 | L6: 8947 | M6: SUP-24Q4-XLS / SUP-25Q4-XLS / SUP-26Q2-XLS | N6: Financial Highlights Page 2 / Statements of Income Page 5 | O6: Single-quarter reported values; PPPT and tax rate are model calculations where applicable
A7: Total Revenue | B7: CAD millions | C7: 13485 | D7: 14154 | E7: 14631 | F7: 15074 | G7: 16739 | H7: 15672 | I7: 16985 | J7: 17209 | K7: 17960 | L7: 17453 | M7: SUP-24Q4-XLS / SUP-25Q4-XLS / SUP-26Q2-XLS | N7: Financial Highlights Page 2 / Statements of Income Page 5 | O7: Single-quarter reported values; PPPT and tax rate are model calculations where applicable
A8: Provision for Credit Losses | B8: CAD millions | C8: 813 | D8: 920 | E8: 659 | F8: 840 | G8: 1050 | H8: 1424 | I8: 881 | J8: 1007 | K8: 1090 | L8: 912 | M8: SUP-24Q4-XLS / SUP-25Q4-XLS / SUP-26Q2-XLS | N8: Financial Highlights Page 2 / Statements of Income Page 5 | O8: Single-quarter reported values; PPPT and tax rate are model calculations where applicable
A9: Non-Interest Expense | B9: CAD millions | C9: 8324 | D9: 8308 | E9: 8599 | F9: 9019 | G9: 9256 | H9: 8730 | I9: 9232 | J9: 9374 | K9: 9463 | L9: 9437 | M9: SUP-24Q4-XLS / SUP-25Q4-XLS / SUP-26Q2-XLS | N9: Financial Highlights Page 2 / Statements of Income Page 5 | O9: Single-quarter reported values; PPPT and tax rate are model calculations where applicable
A10: Income Before Income Taxes | B10: CAD millions | C10: 4348 | D10: 4926 | E10: 5373 | F10: 5215 | G10: 6433 | H10: 5518 | I10: 6872 | J10: 6828 | K10: 7407 | L10: 7104 | M10: SUP-24Q4-XLS / SUP-25Q4-XLS / SUP-26Q2-XLS | N10: Financial Highlights Page 2 / Statements of Income Page 5 | O10: Single-quarter reported values; PPPT and tax rate are model calculations where applicable
A11: Income Taxes | B11: CAD millions | C11: 766 | D11: 976 | E11: 887 | F11: 993 | G11: 1302 | H11: 1128 | I11: 1458 | J11: 1394 | K11: 1622 | L11: 1595 | M11: SUP-24Q4-XLS / SUP-25Q4-XLS / SUP-26Q2-XLS | N11: Financial Highlights Page 2 / Statements of Income Page 5 | O11: Single-quarter reported values; PPPT and tax rate are model calculations where applicable
A12: Net Income | B12: CAD millions | C12: 3582 | D12: 3950 | E12: 4486 | F12: 4222 | G12: 5131 | H12: 4390 | I12: 5414 | J12: 5434 | K12: 5785 | L12: 5509 | M12: SUP-24Q4-XLS / SUP-25Q4-XLS / SUP-26Q2-XLS | N12: Financial Highlights Page 2 / Statements of Income Page 5 | O12: Single-quarter reported values; PPPT and tax rate are model calculations where applicable
A13: Net Income Available to Common Shareholders | B13: CAD millions | C13: 3522 | D13: 3881 | E13: 4377 | F13: 4128 | G13: 5011 | H13: 4274 | I13: 5290 | J13: 5293 | K13: 5643 | L13: 5372 | M13: SUP-24Q4-XLS / SUP-25Q4-XLS / SUP-26Q2-XLS | N13: Financial Highlights Page 2 / Statements of Income Page 5 | O13: Single-quarter reported values; PPPT and tax rate are model calculations where applicable
A14: Diluted EPS | B14: CAD per share | C14: 2.5 | D14: 2.74 | E14: 3.09 | F14: 2.91 | G14: 3.54 | H14: 3.02 | I14: 3.75 | J14: 3.76 | K14: 4.03 | L14: 3.85 | M14: SUP-24Q4-XLS / SUP-25Q4-XLS / SUP-26Q2-XLS | N14: Financial Highlights Page 2 / Statements of Income Page 5 | O14: Single-quarter reported values; PPPT and tax rate are model calculations where applicable
A15: ROE | B15: % | C15: 0.131 | D15: 0.145 | E15: 0.155 | F15: 0.143 | G15: 0.168 | H15: 0.142 | I15: 0.173 | J15: 0.168 | K15: 0.176 | L15: 0.172 | M15: SUP-24Q4-XLS / SUP-25Q4-XLS / SUP-26Q2-XLS | N15: Financial Highlights Page 2 / Statements of Income Page 5 | O15: Single-quarter reported values; PPPT and tax rate are model calculations where applicable
A16: Efficiency Ratio | B16: % | C16: 0.617 | D16: 0.587 | E16: 0.588 | F16: 0.598 | G16: 0.553 | H16: 0.557 | I16: 0.544 | J16: 0.545 | K16: 0.527 | L16: 0.541 | M16: SUP-24Q4-XLS / SUP-25Q4-XLS / SUP-26Q2-XLS | N16: Financial Highlights Page 2 / Statements of Income Page 5 | O16: Single-quarter reported values; PPPT and tax rate are model calculations where applicable
... A19: Effective Tax Rate | B19: % | C19: 0.17617295 | D19: 0.19813236 | E19: 0.16508468 | F19: 0.19041227 | G19: 0.20239391 | H19: 0.20442189 | I19: 0.21216531 | J19: 0.20415934 | K19: 0.21898204 | L19: 0.2245214 | M19: SUP-24Q4-XLS / SUP-25Q4-XLS / SUP-26Q2-XLS | N19: Financial Highlights Page 2 / Statements of Income Page 5 | O19: Single-quarter reported values; PPPT and tax rate are model calculations where applicable

Sheet 07_Raw_Balance_Sheet
A1: RAW BALANCE SHEET
A4: Metric | B4: Unit | C4: FY2023 | D4: FY2024 | E4: FY2025 | F4: Q1 2026 | G4: Q2 2026 | H4: Source ID | I4: Page / Table | J4: Source URL | K4: Notes
A5: Total Assets | B5: CAD millions | C5: 2006531 | D5: 2171582 | E5: 2325006 | F5: 2342393 | G5: 2396080 | H5: SUP-24Q4-XLS / SUP-25Q4-XLS / SUP-26Q2-XLS | I5: Balance Sheets Page 15; Loans Page 21 | J5: https://www.rbc.com/investor-relations/financial-information.html | K5: Period-end reported balances
A6: Cash and Due from Banks | B6: CAD millions | C6: 61989 | D6: 56723 | E6: 37024 | F6: 46226 | G6: 59347 | H6: SUP-24Q4-XLS / SUP-25Q4-XLS / SUP-26Q2-XLS | I6: Balance Sheets Page 15; Loans Page 21 | J6: https://www.rbc.com/investor-relations/financial-information.html | K6: Period-end reported balances
A7: Interest-bearing Deposits with Banks | B7: CAD millions | C7: 71086 | D7: 66020 | E7: 50364 | F7: 53073 | G7: 34146 | H7: SUP-24Q4-XLS / SUP-25Q4-XLS / SUP-26Q2-XLS | I7: Balance Sheets Page 15; Loans Page 21 | J7: https://www.rbc.com/investor-relations/financial-information.html | K7: Period-end reported balances
A8: Securities | B8: CAD millions | C8: 409730 | D8: 439918 | E8: 561788 | F8: 588966 | G8: 612364 | H8: SUP-24Q4-XLS / SUP-25Q4-XLS / SUP-26Q2-XLS | I8: Balance Sheets Page 15; Loans Page 21 | J8: https://www.rbc.com/investor-relations/financial-information.html | K8: Period-end reported balances
A9: Loans, Gross | B9: CAD millions | C9: 857777 | D9: 987417 | E9: 1049515 | F9: 1062282 | G9: 1085470 | H9: SUP-24Q4-XLS / SUP-25Q4-XLS / SUP-26Q2-XLS | I9: Balance Sheets Page 15; Loans Page 21 | J9: https://www.rbc.com/investor-relations/financial-information.html | K9: Period-end reported balances
A10: Allowance for Loan Losses | B10: CAD millions | C10: -5004 | D10: -6037 | E10: -7093 | F10: -7401 | G10: -7521 | H10: SUP-24Q4-XLS / SUP-25Q4-XLS / SUP-26Q2-XLS | I10: Balance Sheets Page 15; Loans Page 21 | J10: https://www.rbc.com/investor-relations/financial-information.html | K10: Period-end reported balances
A11: Loans, Net of Allowance | B11: CAD millions | C11: 852773 | D11: 981380 | E11: 1042422 | F11: 1054881 | G11: 1077949 | H11: SUP-24Q4-XLS / SUP-25Q4-XLS / SUP-26Q2-XLS | I11: Balance Sheets Page 15; Loans Page 21 | J11: https://www.rbc.com/investor-relations/financial-information.html | K11: Period-end reported balances
A12: Residential Mortgages | B12: CAD millions | C12: 434501 | D12: 477544 | E12: 493413 | F12: 496529 | G12: 500879 | H12: SUP-24Q4-XLS / SUP-25Q4-XLS / SUP-26Q2-XLS | I12: Balance Sheets Page 15; Loans Page 21 | J12: https://www.rbc.com/investor-relations/financial-information.html | K12: Period-end reported balances
A13: Personal Loans | B13: CAD millions | C13: 98734 | D13: 108338 | E13: 115345 | F13: 115489 | G13: 117720 | H13: SUP-24Q4-XLS / SUP-25Q4-XLS / SUP-26Q2-XLS | I13: Balance Sheets Page 15; Loans Page 21 | J13: https://www.rbc.com/investor-relations/financial-information.html | K13: Period-end reported balances
A14: Credit Cards | B14: CAD millions | C14: 23035 | D14: 25565 | E14: 26789 | F14: 26489 | G14: 27702 | H14: SUP-24Q4-XLS / SUP-25Q4-XLS / SUP-26Q2-XLS | I14: Balance Sheets Page 15; Loans Page 21 | J14: https://www.rbc.com/investor-relations/financial-information.html | K14: Period-end reported balances
A15: Business and Government Loans | B15: CAD millions | C15: 309571 | D15: 360474 | E15: 397190 | F15: 406864 | G15: 422154 | H15: SUP-24Q4-XLS / SUP-25Q4-XLS / SUP-26Q2-XLS | I15: Balance Sheets Page 15; Loans Page 21 | J15: https://www.rbc.com/investor-relations/financial-information.html | K15: Period-end reported balances
A16: Other Assets | B16: CAD millions | C16: 81371 | D16: 92190 | E16: 112893 | F16: 115296 | G16: 111841 | H16: SUP-24Q4-XLS / SUP-25Q4-XLS / SUP-26Q2-XLS | I16: Balance Sheets Page 15; Loans Page 21 | J16: https://www.rbc.com/investor-relations/financial-information.html | K16: Period-end reported balances
... A25: Loans and Acceptances | B25: CAD millions | C25: 879522 | D25: 987452 | E25: 1049534 | F25: 1062298 | G25: 1085510 | H25: SUP-24Q4-XLS / SUP-25Q4-XLS / SUP-26Q2-XLS | I25: Balance Sheets Page 15; Loans Page 21 | J25: https://www.rbc.com/investor-relations/financial-information.html | K25: Period-end reported balances

Sheet 08_Raw_Credit_Quality
A1: RAW CREDIT QUALITY
A4: Metric | B4: Unit | C4: FY2023 | D4: FY2024 | E4: FY2025 | F4: Q1 2026 | G4: Q2 2026 | H4: Source ID | I4: Page / Table | J4: Source URL | K4: Notes
A5: Total PCL | B5: CAD millions | C5: 2468 | D5: 3232 | E5: 4362 | F5: 1090 | G5: 912 | H5: SUP-24Q4-XLS / SUP-25Q4-XLS / SUP-26Q2-XLS | I5: Credit Quality Pages 22, 25, 27 and 29 | J5: https://www.rbc.com/investor-relations/financial-information.html | K5: Reported amount
A6: PCL on Performing Loans | B6: CAD millions | C6: 660 | D6: 627 | E6: 622 | F6: 28 | G6: 18 | H6: SUP-24Q4-XLS / SUP-25Q4-XLS / SUP-26Q2-XLS | I6: Credit Quality Pages 22, 25, 27 and 29 | J6: https://www.rbc.com/investor-relations/financial-information.html | K6: Reported amount
A7: PCL on Impaired Loans | B7: CAD millions | C7: 1836 | D7: 2620 | E7: 3734 | F7: 1068 | G7: 899 | H7: SUP-24Q4-XLS / SUP-25Q4-XLS / SUP-26Q2-XLS | I7: Credit Quality Pages 22, 25, 27 and 29 | J7: https://www.rbc.com/investor-relations/financial-information.html | K7: Reported amount
A8: PCL on Loans Ratio | B8: % | C8: 0.0029 | D8: 0.0035 | E8: 0.0043 | F8: 0.0041 | G8: 0.0035 | H8: SUP-24Q4-XLS / SUP-25Q4-XLS / SUP-26Q2-XLS | I8: Credit Quality Pages 22, 25, 27 and 29 | J8: https://www.rbc.com/investor-relations/financial-information.html | K8: Reported ratio; quarterly ratios are annualized where RBC presents them
A9: Gross Impaired Loans | B9: CAD millions | C9: 3704 | D9: 5867 | E9: 8682 | F9: 9167 | G9: 9790 | H9: SUP-24Q4-XLS / SUP-25Q4-XLS / SUP-26Q2-XLS | I9: Credit Quality Pages 22, 25, 27 and 29 | J9: https://www.rbc.com/investor-relations/financial-information.html | K9: Reported amount
A10: GIL Ratio | B10: % | C10: 0.0042 | D10: 0.0059 | E10: 0.0083 | F10: 0.0086 | G10: 0.009 | H10: SUP-24Q4-XLS / SUP-25Q4-XLS / SUP-26Q2-XLS | I10: Credit Quality Pages 22, 25, 27 and 29 | J10: https://www.rbc.com/investor-relations/financial-information.html | K10: Reported ratio; quarterly ratios are annualized where RBC presents them
A11: Allowance for Credit Losses | B11: CAD millions | C11: 5366 | D11: 6364 | E11: 7470 | F11: 7767 | G11: 7819 | H11: SUP-24Q4-XLS / SUP-25Q4-XLS / SUP-26Q2-XLS | I11: Credit Quality Pages 22, 25, 27 and 29 | J11: https://www.rbc.com/investor-relations/financial-information.html | K11: Reported amount
A12: ACL on Performing Loans | B12: CAD millions | C12: 4200 | D12: 4836 | E12: 5473 | F12: 5471 | G12: 5487 | H12: SUP-24Q4-XLS / SUP-25Q4-XLS / SUP-26Q2-XLS | I12: Credit Quality Pages 22, 25, 27 and 29 | J12: https://www.rbc.com/investor-relations/financial-information.html | K12: Reported amount
A13: ACL on Impaired Loans | B13: CAD millions | C13: 1148 | D13: 1516 | E13: 1986 | F13: 2281 | G13: 2317 | H13: SUP-24Q4-XLS / SUP-25Q4-XLS / SUP-26Q2-XLS | I13: Credit Quality Pages 22, 25, 27 and 29 | J13: https://www.rbc.com/investor-relations/financial-information.html | K13: Reported amount
A14: ACL-to-Loans Ratio | B14: % | C14: 0.0061 | D14: 0.0064 | E14: 0.0071 | F14: 0.0073 | G14: 0.0072 | H14: SUP-24Q4-XLS / SUP-25Q4-XLS / SUP-26Q2-XLS | I14: Credit Quality Pages 22, 25, 27 and 29 | J14: https://www.rbc.com/investor-relations/financial-information.html | K14: Reported ratio; quarterly ratios are annualized where RBC presents them
A15: Stage 3 ACL / GIL | B15: % | C15: 0.31 | D15: 0.2585 | E15: 0.2288 | F15: 0.2488 | G15: 0.2367 | H15: SUP-24Q4-XLS / SUP-25Q4-XLS / SUP-26Q2-XLS | I15: Credit Quality Pages 22, 25, 27 and 29 | J15: https://www.rbc.com/investor-relations/financial-information.html | K15: Reported ratio; quarterly ratios are annualized where RBC presents them
A16: Net Write-Off Ratio | B16: % | C16: 0.0014 | D16: 0.0022 | E16: 0.0028 | F16: 0.0024 | G16: 0.0028 | H16: SUP-24Q4-XLS / SUP-25Q4-XLS / SUP-26Q2-XLS | I16: Credit Quality Pages 22, 25, 27 and 29 | J16: https://www.rbc.com/investor-relations/financial-information.html | K16: Corrected to RBC-reported FY2023 annual net write-off ratio of 0.14%

Sheet 09_Raw_Capital_Liquidity
A1: RAW CAPITAL AND LIQUIDITY
A4: Metric | B4: Unit | C4: FY2023 | D4: FY2024 | E4: FY2025 | F4: Q1 2026 | G4: Q2 2026 | H4: Source ID | I4: Page / Table | J4: Source URL | K4: Notes
A5: CET1 Capital | B5: CAD millions | C5: 86611 | D5: 88936 | E5: 98748 | F5: 100415 | G5: 101313 | H5: AR-25 / SUP-26Q2-XLS / P3-26Q2-XLS | I5: Capital Pages 19–20; Annual Report liquidity pages 96–99; Pillar 3 KM1 | J5: https://www.rbc.com/investor-relations/financial-information.html | K5: Blank where a comparable period was not consistently collected
A6: Tier 1 Capital | B6: CAD millions | C6: 93904 | D6: 97952 | E6: 110393 | F6: 111549 | G6: 112453 | H6: AR-25 / SUP-26Q2-XLS / P3-26Q2-XLS | I6: Capital Pages 19–20; Annual Report liquidity pages 96–99; Pillar 3 KM1 | J6: https://www.rbc.com/investor-relations/financial-information.html | K6: Blank where a comparable period was not consistently collected
A7: Total Capital | B7: CAD millions | C7: 104952 | D7: 110487 | E7: 122399 | F7: 123732 | G7: 126286 | H7: AR-25 / SUP-26Q2-XLS / P3-26Q2-XLS | I7: Capital Pages 19–20; Annual Report liquidity pages 96–99; Pillar 3 KM1 | J7: https://www.rbc.com/investor-relations/financial-information.html | K7: Blank where a comparable period was not consistently collected
A8: Total Risk-Weighted Assets | B8: CAD millions | C8: 596223 | D8: 672282 | E8: 730225 | F8: 734693 | G8: 748590 | H8: AR-25 / SUP-26Q2-XLS / P3-26Q2-XLS | I8: Capital Pages 19–20; Annual Report liquidity pages 96–99; Pillar 3 KM1 | J8: https://www.rbc.com/investor-relations/financial-information.html | K8: Blank where a comparable period was not consistently collected
A9: CET1 Ratio | B9: % | C9: 0.145 | D9: 0.132 | E9: 0.135 | F9: 0.137 | G9: 0.135 | H9: AR-25 / SUP-26Q2-XLS / P3-26Q2-XLS | I9: Capital Pages 19–20; Annual Report liquidity pages 96–99; Pillar 3 KM1 | J9: https://www.rbc.com/investor-relations/financial-information.html | K9: Blank where a comparable period was not consistently collected
A10: Tier 1 Capital Ratio | B10: % | C10: 0.157 | D10: 0.146 | E10: 0.151 | F10: 0.152 | G10: 0.15 | H10: AR-25 / SUP-26Q2-XLS / P3-26Q2-XLS | I10: Capital Pages 19–20; Annual Report liquidity pages 96–99; Pillar 3 KM1 | J10: https://www.rbc.com/investor-relations/financial-information.html | K10: Blank where a comparable period was not consistently collected
A11: Total Capital Ratio | B11: % | C11: 0.176 | D11: 0.164 | E11: 0.168 | F11: 0.168 | G11: 0.169 | H11: AR-25 / SUP-26Q2-XLS / P3-26Q2-XLS | I11: Capital Pages 19–20; Annual Report liquidity pages 96–99; Pillar 3 KM1 | J11: https://www.rbc.com/investor-relations/financial-information.html | K11: Blank where a comparable period was not consistently collected
A12: Leverage Ratio | B12: % | C12: 0.043 | D12: 0.042 | E12: 0.044 | F12: 0.044 | G12: 0.043 | H12: AR-25 / SUP-26Q2-XLS / P3-26Q2-XLS | I12: Capital Pages 19–20; Annual Report liquidity pages 96–99; Pillar 3 KM1 | J12: https://www.rbc.com/investor-relations/financial-information.html | K12: Blank where a comparable period was not consistently collected
A13: Liquidity Coverage Ratio | B13: % | D13: 1.28 | E13: 1.27 | F13: 1.24 | G13: 1.26 | H13: AR-25 / SUP-26Q2-XLS / P3-26Q2-XLS | I13: Capital Pages 19–20; Annual Report liquidity pages 96–99; Pillar 3 KM1 | J13: https://www.rbc.com/investor-relations/financial-information.html | K13: FY2024–FY2025 are annual average LCRs; Q1–Q2 2026 are quarterly average LCRs
A14: Net Stable Funding Ratio | B14: % | D14: 1.14 | E14: 1.12 | F14: 1.11 | G14: 1.11 | H14: AR-25 / SUP-26Q2-XLS / P3-26Q2-XLS | I14: Capital Pages 19–20; Annual Report liquidity pages 96–99; Pillar 3 KM1 | J14: https://www.rbc.com/investor-relations/financial-information.html | K14: FY2024–FY2025 are annual average NSFRs; Q1–Q2 2026 are quarter-end NSFRs
A15: Common Shareholders' Equity | B15: CAD millions | C15: 107734 | D15: 118058 | E15: 127417 | F15: 128670 | G15: 129579 | H15: AR-25 / SUP-26Q2-XLS / P3-26Q2-XLS | I15: Capital Pages 19–20; Annual Report liquidity pages 96–99; Pillar 3 KM1 | J15: https://www.rbc.com/investor-relations/financial-information.html | K15: Blank where a comparable period was not consistently collected
A16: Dividends Per Common Share | B16: CAD per share | C16: 5.4 | D16: 5.6 | E16: 6.04 | F16: 1.64 | G16: 1.64 | H16: AR-25 / SUP-26Q2-XLS / P3-26Q2-XLS | I16: Capital Pages 19–20; Annual Report liquidity pages 96–99; Pillar 3 KM1 | J16: https://www.rbc.com/investor-relations/financial-information.html | K16: Annual dividends declared per share for FY2023–FY2025; quarterly declarations for Q1–Q2 2026

Sheet 10_Raw_Segment_Results
A1: RAW SEGMENT RESULTS
A4: Period | B4: Segment | C4: Total Revenue | D4: Net Interest Income | E4: Non-Interest Income | F4: PCL | G4: Non-Interest Expense | H4: Net Income | I4: ROE | J4: Efficiency Ratio | K4: Source ID | L4: Notes
A5: FY2023 | B5: Personal Banking | C5: 15471 | D5: 10945 | E5: 4526 | F5: 1264 | G5: 6813 | H5: 5418 | I5: 0.289 | J5: 0.44 | K5: SUP-24Q4-XLS / SUP-25Q4-XLS / SUP-26Q2-XLS | L5: Verified against the relevant RBC segment schedule; TEB presentation applies to Capital Markets and Corporate Support
A6: FY2023 | B6: Commercial Banking | C6: 6032 | D6: 4771 | E6: 1261 | F6: 315 | G6: 2143 | H6: 2582 | I6: 0.237 | J6: 0.355 | K6: SUP-24Q4-XLS / SUP-25Q4-XLS / SUP-26Q2-XLS | L6: Verified against the relevant RBC segment schedule; TEB presentation applies to Capital Markets and Corporate Support
A7: FY2023 | B7: Wealth Management | C7: 18161 | D7: 4853 | E7: 13308 | F7: 328 | G7: 14387 | H7: 2693 | I7: 0.109 | K7: SUP-24Q4-XLS / SUP-25Q4-XLS / SUP-26Q2-XLS | L7: Verified against the relevant RBC segment schedule; TEB presentation applies to Capital Markets and Corporate Support
A8: FY2023 | B8: Insurance | C8: 1010 | F8: 0 | G8: 293 | H8: 549 | I8: 0.253 | K8: SUP-24Q4-XLS / SUP-25Q4-XLS / SUP-26Q2-XLS | L8: Verified against the relevant RBC segment schedule; TEB presentation applies to Capital Markets and Corporate Support
A9: FY2023 | B9: Capital Markets | C9: 11051 | D9: 3379 | E9: 7672 | F9: 561 | G9: 6509 | H9: 4139 | I9: 0.146 | K9: SUP-24Q4-XLS / SUP-25Q4-XLS / SUP-26Q2-XLS | L9: Verified against the relevant RBC segment schedule; TEB presentation applies to Capital Markets and Corporate Support
A10: FY2023 | B10: Corporate Support | C10: -261 | D10: 1181 | E10: -1553 | F10: 0 | G10: 559 | H10: -769 | K10: SUP-24Q4-XLS / SUP-25Q4-XLS / SUP-26Q2-XLS | L10: Verified against the relevant RBC segment schedule; TEB presentation applies to Capital Markets and Corporate Support
A11: FY2024 | B11: Personal Banking | C11: 17342 | D11: 12438 | E11: 4904 | F11: 1802 | G11: 7485 | H11: 5921 | I11: 0.248 | J11: 0.432 | K11: SUP-24Q4-XLS / SUP-25Q4-XLS / SUP-26Q2-XLS | L11: Verified against the relevant RBC segment schedule; TEB presentation applies to Capital Markets and Corporate Support
A12: FY2024 | B12: Commercial Banking | C12: 7382 | D12: 6061 | E12: 1321 | F12: 975 | G12: 2512 | H12: 2818 | I12: 0.185 | J12: 0.34 | K12: SUP-24Q4-XLS / SUP-25Q4-XLS / SUP-26Q2-XLS | L12: Verified against the relevant RBC segment schedule; TEB presentation applies to Capital Markets and Corporate Support
A13: FY2024 | B13: Wealth Management | C13: 19626 | D13: 4979 | E13: 14647 | F13: 29 | G13: 15312 | H13: 3422 | I13: 0.144 | K13: SUP-24Q4-XLS / SUP-25Q4-XLS / SUP-26Q2-XLS | L13: Verified against the relevant RBC segment schedule; TEB presentation applies to Capital Markets and Corporate Support
A14: FY2024 | B14: Insurance | C14: 1224 | F14: 0 | G14: 285 | H14: 729 | I14: 0.353 | K14: SUP-24Q4-XLS / SUP-25Q4-XLS / SUP-26Q2-XLS | L14: Verified against the relevant RBC segment schedule; TEB presentation applies to Capital Markets and Corporate Support
A15: FY2024 | B15: Capital Markets | C15: 12012 | D15: 3183 | E15: 8829 | F15: 424 | G15: 7016 | H15: 4573 | I15: 0.142 | K15: SUP-24Q4-XLS / SUP-25Q4-XLS / SUP-26Q2-XLS | L15: Verified against the relevant RBC segment schedule; TEB presentation applies to Capital Markets and Corporate Support
A16: FY2024 | B16: Corporate Support | C16: -242 | D16: 1292 | E16: -2033 | F16: 0 | G16: 1167 | H16: -1223 | K16: SUP-24Q4-XLS / SUP-25Q4-XLS / SUP-26Q2-XLS | L16: Verified against the relevant RBC segment schedule; TEB presentation applies to Capital Markets and Corporate Support
A17: FY2025 | B17: Personal Banking | C17: 19854 | D17: 14496 | E17: 5358 | F17: 2105 | G17: 8001 | H17: 7105 | I17: 0.249 | J17: 0.403 | K17: SUP-24Q4-XLS / SUP-25Q4-XLS / SUP-26Q2-XLS | L17: Verified against the relevant RBC segment schedule; TEB presentation applies to Capital Markets and Corporate Support
A18: FY2025 | B18: Commercial Banking | C18: 8562 | D18: 7268 | E18: 1294 | F18: 1550 | G18: 2833 | H18: 3020 | I18: 0.149 | J18: 0.331 | K18: SUP-24Q4-XLS / SUP-25Q4-XLS / SUP-26Q2-XLS | L18: Verified against the relevant RBC segment schedule; TEB presentation applies to Capital Markets and Corporate Support
A19: FY2025 | B19: Wealth Management | C19: 22378 | D19: 5459 | E19: 16919 | F19: 120 | G19: 16769 | H19: 4289 | I19: 0.166 | K19: SUP-24Q4-XLS / SUP-25Q4-XLS / SUP-26Q2-XLS | L19: Verified against the relevant RBC segment schedule; TEB presentation applies to Capital Markets and Corporate Support
A20: FY2025 | B20: Insurance | C20: 1321 | F20: 0 | G20: 315 | H20: 828 | I20: 0.407 | K20: SUP-24Q4-XLS / SUP-25Q4-XLS / SUP-26Q2-XLS | L20: Verified against the relevant RBC segment schedule; TEB presentation applies to Capital Markets and Corporate Support
A21: FY2025 | B21: Capital Markets | C21: 14426 | D21: 4789 | E21: 9637 | F21: 587 | G21: 7966 | H21: 5393 | I21: 0.137 | K21: SUP-24Q4-XLS / SUP-25Q4-XLS / SUP-26Q2-XLS | L21: Verified against the relevant RBC segment schedule; TEB presentation applies to Capital Markets and Corporate Support
A22: FY2025 | B22: Corporate Support | C22: 64 | D22: 988 | E22: -1329 | F22: 0 | G22: 317 | H22: -266 | K22: SUP-24Q4-XLS / SUP-25Q4-XLS / SUP-26Q2-XLS | L22: Verified against the relevant RBC segment schedule; TEB presentation applies to Capital Markets and Corporate Support
A23: Q1 2026 | B23: Personal Banking | C23: 5238 | D23: 3831 | E23: 1407 | F23: 531 | G23: 2020 | H23: 1962 | I23: 0.263 | J23: 0.386 | K23: SUP-24Q4-XLS / SUP-25Q4-XLS / SUP-26Q2-XLS | L23: Verified against the relevant RBC segment schedule; TEB presentation applies to Capital Markets and Corporate Support
A24: Q1 2026 | B24: Commercial Banking | C24: 2207 | D24: 1895 | E24: 312 | F24: 286 | G24: 725 | H24: 863 | I24: 0.169 | J24: 0.329 | K24: SUP-24Q4-XLS / SUP-25Q4-XLS / SUP-26Q2-XLS | L24: Verified against the relevant RBC segment schedule; TEB presentation applies to Capital Markets and Corporate Support
A25: Q1 2026 | B25: Wealth Management | C25: 6084 | D25: 1454 | E25: 4630 | F25: 18 | G25: 4384 | H25: 1295 | I25: 0.196 | K25: SUP-24Q4-XLS / SUP-25Q4-XLS / SUP-26Q2-XLS | L25: Verified against the relevant RBC segment schedule; TEB presentation applies to Capital Markets and Corporate Support
A26: Q1 2026 | B26: Insurance | C26: 338 | F26: 0 | G26: 78 | H26: 213 | I26: 0.249 | K26: SUP-24Q4-XLS / SUP-25Q4-XLS / SUP-26Q2-XLS | L26: Verified against the relevant RBC segment schedule; TEB presentation applies to Capital Markets and Corporate Support
A27: Q1 2026 | B27: Capital Markets | C27: 4018 | D27: 1218 | E27: 2800 | F27: 256 | G27: 2119 | H27: 1478 | I27: 0.144 | K27: SUP-24Q4-XLS / SUP-25Q4-XLS / SUP-26Q2-XLS | L27: Verified against the relevant RBC segment schedule; TEB presentation applies to Capital Markets and Corporate Support
A28: Q1 2026 | B28: Corporate Support | C28: 75 | D28: 187 | E28: -202 | F28: -1 | G28: 51 | H28: -26 | K28: SUP-24Q4-XLS / SUP-25Q4-XLS / SUP-26Q2-XLS | L28: Verified against the relevant RBC segment schedule; TEB presentation applies to Capital Markets and Corporate Support
A29: Q2 2026 | B29: Personal Banking | C29: 5049 | D29: 3715 | E29: 1334 | F29: 492 | G29: 1987 | H29: 1870 | I29: 0.254 | J29: 0.394 | K29: SUP-24Q4-XLS / SUP-25Q4-XLS / SUP-26Q2-XLS | L29: Verified against the relevant RBC segment schedule; TEB presentation applies to Capital Markets and Corporate Support
A30: Q2 2026 | B30: Commercial Banking | C30: 2159 | D30: 1844 | E30: 315 | F30: 247 | G30: 730 | H30: 854 | I30: 0.174 | J30: 0.338 | K30: SUP-24Q4-XLS / SUP-25Q4-XLS / SUP-26Q2-XLS | L30: Verified against the relevant RBC segment schedule; TEB presentation applies to Capital Markets and Corporate Support
A31: Q2 2026 | B31: Wealth Management | C31: 5954 | D31: 1429 | E31: 4525 | F31: 55 | G31: 4379 | H31: 1185 | I31: 0.186 | K31: SUP-24Q4-XLS / SUP-25Q4-XLS / SUP-26Q2-XLS | L31: Verified against the relevant RBC segment schedule; TEB presentation applies to Capital Markets and Corporate Support
A32: Q2 2026 | B32: Insurance | C32: 345 | F32: 0 | G32: 75 | H32: 218 | I32: 0.259 | K32: SUP-24Q4-XLS / SUP-25Q4-XLS / SUP-26Q2-XLS | L32: Verified against the relevant RBC segment schedule; TEB presentation applies to Capital Markets and Corporate Support
A33: Q2 2026 | B33: Capital Markets | C33: 3943 | D33: 1315 | E33: 2628 | F33: 117 | G33: 2097 | H33: 1484 | I33: 0.148 | K33: SUP-24Q4-XLS / SUP-25Q4-XLS / SUP-26Q2-XLS | L33: Verified against the relevant RBC segment schedule; TEB presentation applies to Capital Markets and Corporate Support
A34: Q2 2026 | B34: Corporate Support | C34: 3 | D34: 203 | E34: -279 | F34: 1 | G34: 95 | H34: -102 | K34: SUP-24Q4-XLS / SUP-25Q4-XLS / SUP-26Q2-XLS | L34: Verified against the relevant RBC segment schedule; TEB presentation applies to Capital Markets and Corporate Support

Sheet 11_STD_Performance
A1: STANDARDIZED PERFORMANCE
A4: Metric | B4: FY2023 | C4: FY2024 | D4: FY2025
A5: Net Interest Income | B5: =IFERROR(INDEX('05_Raw_Annual_Performance'!$C$5:$E$100,MATCH($A5,'05_Raw_Annual_Performance'!$A$5:$A$100,0),MATCH(B$4,'05_Raw_Annual_Performance'!$C$4:$E$4,0)),"") -> 25129 | C5: =IFERROR(INDEX('05_Raw_Annual_Performance'!$C$5:$E$100,MATCH($A5,'05_Raw_Annual_Performance'!$A$5:$A$100,0),MATCH(C$4,'05_Raw_Annual_Performance'!$C$4:$E$4,0)),"") -> 27953 | D5: =IFERROR(INDEX('05_Raw_Annual_Performance'!$C$5:$E$100,MATCH($A5,'05_Raw_Annual_Performance'!$A$5:$A$100,0),MATCH(D$4,'05_Raw_Annual_Performance'!$C$4:$E$4,0)),"") -> 33000
A6: Non-Interest Income | B6: =IFERROR(INDEX('05_Raw_Annual_Performance'!$C$5:$E$100,MATCH($A6,'05_Raw_Annual_Performance'!$A$5:$A$100,0),MATCH(B$4,'05_Raw_Annual_Performance'!$C$4:$E$4,0)),"") -> 26335 | C6: =IFERROR(INDEX('05_Raw_Annual_Performance'!$C$5:$E$100,MATCH($A6,'05_Raw_Annual_Performance'!$A$5:$A$100,0),MATCH(C$4,'05_Raw_Annual_Performance'!$C$4:$E$4,0)),"") -> 29391 | D6: =IFERROR(INDEX('05_Raw_Annual_Performance'!$C$5:$E$100,MATCH($A6,'05_Raw_Annual_Performance'!$A$5:$A$100,0),MATCH(D$4,'05_Raw_Annual_Performance'!$C$4:$E$4,0)),"") -> 33605
A7: Total Revenue | B7: =IFERROR(INDEX('05_Raw_Annual_Performance'!$C$5:$E$100,MATCH($A7,'05_Raw_Annual_Performance'!$A$5:$A$100,0),MATCH(B$4,'05_Raw_Annual_Performance'!$C$4:$E$4,0)),"") -> 51464 | C7: =IFERROR(INDEX('05_Raw_Annual_Performance'!$C$5:$E$100,MATCH($A7,'05_Raw_Annual_Performance'!$A$5:$A$100,0),MATCH(C$4,'05_Raw_Annual_Performance'!$C$4:$E$4,0)),"") -> 57344 | D7: =IFERROR(INDEX('05_Raw_Annual_Performance'!$C$5:$E$100,MATCH($A7,'05_Raw_Annual_Performance'!$A$5:$A$100,0),MATCH(D$4,'05_Raw_Annual_Performance'!$C$4:$E$4,0)),"") -> 66605
A8: Provision for Credit Losses | B8: =IFERROR(INDEX('05_Raw_Annual_Performance'!$C$5:$E$100,MATCH($A8,'05_Raw_Annual_Performance'!$A$5:$A$100,0),MATCH(B$4,'05_Raw_Annual_Performance'!$C$4:$E$4,0)),"") -> 2468 | C8: =IFERROR(INDEX('05_Raw_Annual_Performance'!$C$5:$E$100,MATCH($A8,'05_Raw_Annual_Performance'!$A$5:$A$100,0),MATCH(C$4,'05_Raw_Annual_Performance'!$C$4:$E$4,0)),"") -> 3232 | D8: =IFERROR(INDEX('05_Raw_Annual_Performance'!$C$5:$E$100,MATCH($A8,'05_Raw_Annual_Performance'!$A$5:$A$100,0),MATCH(D$4,'05_Raw_Annual_Performance'!$C$4:$E$4,0)),"") -> 4362
A9: Non-Interest Expense | B9: =IFERROR(INDEX('05_Raw_Annual_Performance'!$C$5:$E$100,MATCH($A9,'05_Raw_Annual_Performance'!$A$5:$A$100,0),MATCH(B$4,'05_Raw_Annual_Performance'!$C$4:$E$4,0)),"") -> 30813 | C9: =IFERROR(INDEX('05_Raw_Annual_Performance'!$C$5:$E$100,MATCH($A9,'05_Raw_Annual_Performance'!$A$5:$A$100,0),MATCH(C$4,'05_Raw_Annual_Performance'!$C$4:$E$4,0)),"") -> 34250 | D9: =IFERROR(INDEX('05_Raw_Annual_Performance'!$C$5:$E$100,MATCH($A9,'05_Raw_Annual_Performance'!$A$5:$A$100,0),MATCH(D$4,'05_Raw_Annual_Performance'!$C$4:$E$4,0)),"") -> 36592
A10: Income Before Income Taxes | B10: =IFERROR(INDEX('05_Raw_Annual_Performance'!$C$5:$E$100,MATCH($A10,'05_Raw_Annual_Performance'!$A$5:$A$100,0),MATCH(B$4,'05_Raw_Annual_Performance'!$C$4:$E$4,0)),"") -> 18183 | C10: =IFERROR(INDEX('05_Raw_Annual_Performance'!$C$5:$E$100,MATCH($A10,'05_Raw_Annual_Performance'!$A$5:$A$100,0),MATCH(C$4,'05_Raw_Annual_Performance'!$C$4:$E$4,0)),"") -> 19862 | D10: =IFERROR(INDEX('05_Raw_Annual_Performance'!$C$5:$E$100,MATCH($A10,'05_Raw_Annual_Performance'!$A$5:$A$100,0),MATCH(D$4,'05_Raw_Annual_Performance'!$C$4:$E$4,0)),"") -> 25651
A11: Income Taxes | B11: =IFERROR(INDEX('05_Raw_Annual_Performance'!$C$5:$E$100,MATCH($A11,'05_Raw_Annual_Performance'!$A$5:$A$100,0),MATCH(B$4,'05_Raw_Annual_Performance'!$C$4:$E$4,0)),"") -> 3571 | C11: =IFERROR(INDEX('05_Raw_Annual_Performance'!$C$5:$E$100,MATCH($A11,'05_Raw_Annual_Performance'!$A$5:$A$100,0),MATCH(C$4,'05_Raw_Annual_Performance'!$C$4:$E$4,0)),"") -> 3622 | D11: =IFERROR(INDEX('05_Raw_Annual_Performance'!$C$5:$E$100,MATCH($A11,'05_Raw_Annual_Performance'!$A$5:$A$100,0),MATCH(D$4,'05_Raw_Annual_Performance'!$C$4:$E$4,0)),"") -> 5282
A12: Net Income | B12: =IFERROR(INDEX('05_Raw_Annual_Performance'!$C$5:$E$100,MATCH($A12,'05_Raw_Annual_Performance'!$A$5:$A$100,0),MATCH(B$4,'05_Raw_Annual_Performance'!$C$4:$E$4,0)),"") -> 14612 | C12: =IFERROR(INDEX('05_Raw_Annual_Performance'!$C$5:$E$100,MATCH($A12,'05_Raw_Annual_Performance'!$A$5:$A$100,0),MATCH(C$4,'05_Raw_Annual_Performance'!$C$4:$E$4,0)),"") -> 16240 | D12: =IFERROR(INDEX('05_Raw_Annual_Performance'!$C$5:$E$100,MATCH($A12,'05_Raw_Annual_Performance'!$A$5:$A$100,0),MATCH(D$4,'05_Raw_Annual_Performance'!$C$4:$E$4,0)),"") -> 20369
A13: Net Income Available to Common Shareholders | B13: =IFERROR(INDEX('05_Raw_Annual_Performance'!$C$5:$E$100,MATCH($A13,'05_Raw_Annual_Performance'!$A$5:$A$100,0),MATCH(B$4,'05_Raw_Annual_Performance'!$C$4:$E$4,0)),"") -> 14369 | C13: =IFERROR(INDEX('05_Raw_Annual_Performance'!$C$5:$E$100,MATCH($A13,'05_Raw_Annual_Performance'!$A$5:$A$100,0),MATCH(C$4,'05_Raw_Annual_Performance'!$C$4:$E$4,0)),"") -> 15908 | D13: =IFERROR(INDEX('05_Raw_Annual_Performance'!$C$5:$E$100,MATCH($A13,'05_Raw_Annual_Performance'!$A$5:$A$100,0),MATCH(D$4,'05_Raw_Annual_Performance'!$C$4:$E$4,0)),"") -> 19868
A14: Diluted EPS | B14: =IFERROR(INDEX('05_Raw_Annual_Performance'!$C$5:$E$100,MATCH($A14,'05_Raw_Annual_Performance'!$A$5:$A$100,0),MATCH(B$4,'05_Raw_Annual_Performance'!$C$4:$E$4,0)),"") -> 10.32 | C14: =IFERROR(INDEX('05_Raw_Annual_Performance'!$C$5:$E$100,MATCH($A14,'05_Raw_Annual_Performance'!$A$5:$A$100,0),MATCH(C$4,'05_Raw_Annual_Performance'!$C$4:$E$4,0)),"") -> 11.25 | D14: =IFERROR(INDEX('05_Raw_Annual_Performance'!$C$5:$E$100,MATCH($A14,'05_Raw_Annual_Performance'!$A$5:$A$100,0),MATCH(D$4,'05_Raw_Annual_Performance'!$C$4:$E$4,0)),"") -> 14.07
A15: ROE | B15: =IFERROR(INDEX('05_Raw_Annual_Performance'!$C$5:$E$100,MATCH($A15,'05_Raw_Annual_Performance'!$A$5:$A$100,0),MATCH(B$4,'05_Raw_Annual_Performance'!$C$4:$E$4,0)),"") -> 0.143 | C15: =IFERROR(INDEX('05_Raw_Annual_Performance'!$C$5:$E$100,MATCH($A15,'05_Raw_Annual_Performance'!$A$5:$A$100,0),MATCH(C$4,'05_Raw_Annual_Performance'!$C$4:$E$4,0)),"") -> 0.144 | D15: =IFERROR(INDEX('05_Raw_Annual_Performance'!$C$5:$E$100,MATCH($A15,'05_Raw_Annual_Performance'!$A$5:$A$100,0),MATCH(D$4,'05_Raw_Annual_Performance'!$C$4:$E$4,0)),"") -> 0.163
A16: Efficiency Ratio | B16: =IFERROR(INDEX('05_Raw_Annual_Performance'!$C$5:$E$100,MATCH($A16,'05_Raw_Annual_Performance'!$A$5:$A$100,0),MATCH(B$4,'05_Raw_Annual_Performance'!$C$4:$E$4,0)),"") -> 0.599 | C16: =IFERROR(INDEX('05_Raw_Annual_Performance'!$C$5:$E$100,MATCH($A16,'05_Raw_Annual_Performance'!$A$5:$A$100,0),MATCH(C$4,'05_Raw_Annual_Performance'!$C$4:$E$4,0)),"") -> 0.597 | D16: =IFERROR(INDEX('05_Raw_Annual_Performance'!$C$5:$E$100,MATCH($A16,'05_Raw_Annual_Performance'!$A$5:$A$100,0),MATCH(D$4,'05_Raw_Annual_Performance'!$C$4:$E$4,0)),"") -> 0.549
... A19: Effective Tax Rate | B19: =IFERROR(INDEX('05_Raw_Annual_Performance'!$C$5:$E$100,MATCH($A19,'05_Raw_Annual_Performance'!$A$5:$A$100,0),MATCH(B$4,'05_Raw_Annual_Performance'!$C$4:$E$4,0)),"") -> 0.19639223 | C19: =IFERROR(INDEX('05_Raw_Annual_Performance'!$C$5:$E$100,MATCH($A19,'05_Raw_Annual_Performance'!$A$5:$A$100,0),MATCH(C$4,'05_Raw_Annual_Performance'!$C$4:$E$4,0)),"") -> 0.18235827 | D19: =IFERROR(INDEX('05_Raw_Annual_Performance'!$C$5:$E$100,MATCH($A19,'05_Raw_Annual_Performance'!$A$5:$A$100,0),MATCH(D$4,'05_Raw_Annual_Performance'!$C$4:$E$4,0)),"") -> 0.2059179

Sheet 12_STD_Balance_Sheet
A1: STANDARDIZED BALANCE SHEET
A4: Metric | B4: FY2023 | C4: FY2024 | D4: FY2025 | E4: Q1 2026 | F4: Q2 2026
A5: Total Assets | B5: =IFERROR(INDEX('07_Raw_Balance_Sheet'!$C$5:$G$100,MATCH($A5,'07_Raw_Balance_Sheet'!$A$5:$A$100,0),MATCH(B$4,'07_Raw_Balance_Sheet'!$C$4:$G$4,0)),"") -> 2006531 | C5: =IFERROR(INDEX('07_Raw_Balance_Sheet'!$C$5:$G$100,MATCH($A5,'07_Raw_Balance_Sheet'!$A$5:$A$100,0),MATCH(C$4,'07_Raw_Balance_Sheet'!$C$4:$G$4,0)),"") -> 2171582 | D5: =IFERROR(INDEX('07_Raw_Balance_Sheet'!$C$5:$G$100,MATCH($A5,'07_Raw_Balance_Sheet'!$A$5:$A$100,0),MATCH(D$4,'07_Raw_Balance_Sheet'!$C$4:$G$4,0)),"") -> 2325006 | E5: =IFERROR(INDEX('07_Raw_Balance_Sheet'!$C$5:$G$100,MATCH($A5,'07_Raw_Balance_Sheet'!$A$5:$A$100,0),MATCH(E$4,'07_Raw_Balance_Sheet'!$C$4:$G$4,0)),"") -> 2342393 | F5: =IFERROR(INDEX('07_Raw_Balance_Sheet'!$C$5:$G$100,MATCH($A5,'07_Raw_Balance_Sheet'!$A$5:$A$100,0),MATCH(F$4,'07_Raw_Balance_Sheet'!$C$4:$G$4,0)),"") -> 2396080
A6: Cash and Due from Banks | B6: =IFERROR(INDEX('07_Raw_Balance_Sheet'!$C$5:$G$100,MATCH($A6,'07_Raw_Balance_Sheet'!$A$5:$A$100,0),MATCH(B$4,'07_Raw_Balance_Sheet'!$C$4:$G$4,0)),"") -> 61989 | C6: =IFERROR(INDEX('07_Raw_Balance_Sheet'!$C$5:$G$100,MATCH($A6,'07_Raw_Balance_Sheet'!$A$5:$A$100,0),MATCH(C$4,'07_Raw_Balance_Sheet'!$C$4:$G$4,0)),"") -> 56723 | D6: =IFERROR(INDEX('07_Raw_Balance_Sheet'!$C$5:$G$100,MATCH($A6,'07_Raw_Balance_Sheet'!$A$5:$A$100,0),MATCH(D$4,'07_Raw_Balance_Sheet'!$C$4:$G$4,0)),"") -> 37024 | E6: =IFERROR(INDEX('07_Raw_Balance_Sheet'!$C$5:$G$100,MATCH($A6,'07_Raw_Balance_Sheet'!$A$5:$A$100,0),MATCH(E$4,'07_Raw_Balance_Sheet'!$C$4:$G$4,0)),"") -> 46226 | F6: =IFERROR(INDEX('07_Raw_Balance_Sheet'!$C$5:$G$100,MATCH($A6,'07_Raw_Balance_Sheet'!$A$5:$A$100,0),MATCH(F$4,'07_Raw_Balance_Sheet'!$C$4:$G$4,0)),"") -> 59347
A7: Interest-bearing Deposits with Banks | B7: =IFERROR(INDEX('07_Raw_Balance_Sheet'!$C$5:$G$100,MATCH($A7,'07_Raw_Balance_Sheet'!$A$5:$A$100,0),MATCH(B$4,'07_Raw_Balance_Sheet'!$C$4:$G$4,0)),"") -> 71086 | C7: =IFERROR(INDEX('07_Raw_Balance_Sheet'!$C$5:$G$100,MATCH($A7,'07_Raw_Balance_Sheet'!$A$5:$A$100,0),MATCH(C$4,'07_Raw_Balance_Sheet'!$C$4:$G$4,0)),"") -> 66020 | D7: =IFERROR(INDEX('07_Raw_Balance_Sheet'!$C$5:$G$100,MATCH($A7,'07_Raw_Balance_Sheet'!$A$5:$A$100,0),MATCH(D$4,'07_Raw_Balance_Sheet'!$C$4:$G$4,0)),"") -> 50364 | E7: =IFERROR(INDEX('07_Raw_Balance_Sheet'!$C$5:$G$100,MATCH($A7,'07_Raw_Balance_Sheet'!$A$5:$A$100,0),MATCH(E$4,'07_Raw_Balance_Sheet'!$C$4:$G$4,0)),"") -> 53073 | F7: =IFERROR(INDEX('07_Raw_Balance_Sheet'!$C$5:$G$100,MATCH($A7,'07_Raw_Balance_Sheet'!$A$5:$A$100,0),MATCH(F$4,'07_Raw_Balance_Sheet'!$C$4:$G$4,0)),"") -> 34146
A8: Securities | B8: =IFERROR(INDEX('07_Raw_Balance_Sheet'!$C$5:$G$100,MATCH($A8,'07_Raw_Balance_Sheet'!$A$5:$A$100,0),MATCH(B$4,'07_Raw_Balance_Sheet'!$C$4:$G$4,0)),"") -> 409730 | C8: =IFERROR(INDEX('07_Raw_Balance_Sheet'!$C$5:$G$100,MATCH($A8,'07_Raw_Balance_Sheet'!$A$5:$A$100,0),MATCH(C$4,'07_Raw_Balance_Sheet'!$C$4:$G$4,0)),"") -> 439918 | D8: =IFERROR(INDEX('07_Raw_Balance_Sheet'!$C$5:$G$100,MATCH($A8,'07_Raw_Balance_Sheet'!$A$5:$A$100,0),MATCH(D$4,'07_Raw_Balance_Sheet'!$C$4:$G$4,0)),"") -> 561788 | E8: =IFERROR(INDEX('07_Raw_Balance_Sheet'!$C$5:$G$100,MATCH($A8,'07_Raw_Balance_Sheet'!$A$5:$A$100,0),MATCH(E$4,'07_Raw_Balance_Sheet'!$C$4:$G$4,0)),"") -> 588966 | F8: =IFERROR(INDEX('07_Raw_Balance_Sheet'!$C$5:$G$100,MATCH($A8,'07_Raw_Balance_Sheet'!$A$5:$A$100,0),MATCH(F$4,'07_Raw_Balance_Sheet'!$C$4:$G$4,0)),"") -> 612364
A9: Loans, Gross | B9: =IFERROR(INDEX('07_Raw_Balance_Sheet'!$C$5:$G$100,MATCH($A9,'07_Raw_Balance_Sheet'!$A$5:$A$100,0),MATCH(B$4,'07_Raw_Balance_Sheet'!$C$4:$G$4,0)),"") -> 857777 | C9: =IFERROR(INDEX('07_Raw_Balance_Sheet'!$C$5:$G$100,MATCH($A9,'07_Raw_Balance_Sheet'!$A$5:$A$100,0),MATCH(C$4,'07_Raw_Balance_Sheet'!$C$4:$G$4,0)),"") -> 987417 | D9: =IFERROR(INDEX('07_Raw_Balance_Sheet'!$C$5:$G$100,MATCH($A9,'07_Raw_Balance_Sheet'!$A$5:$A$100,0),MATCH(D$4,'07_Raw_Balance_Sheet'!$C$4:$G$4,0)),"") -> 1049515 | E9: =IFERROR(INDEX('07_Raw_Balance_Sheet'!$C$5:$G$100,MATCH($A9,'07_Raw_Balance_Sheet'!$A$5:$A$100,0),MATCH(E$4,'07_Raw_Balance_Sheet'!$C$4:$G$4,0)),"") -> 1062282 | F9: =IFERROR(INDEX('07_Raw_Balance_Sheet'!$C$5:$G$100,MATCH($A9,'07_Raw_Balance_Sheet'!$A$5:$A$100,0),MATCH(F$4,'07_Raw_Balance_Sheet'!$C$4:$G$4,0)),"") -> 1085470
A10: Allowance for Loan Losses | B10: =IFERROR(INDEX('07_Raw_Balance_Sheet'!$C$5:$G$100,MATCH($A10,'07_Raw_Balance_Sheet'!$A$5:$A$100,0),MATCH(B$4,'07_Raw_Balance_Sheet'!$C$4:$G$4,0)),"") -> -5004 | C10: =IFERROR(INDEX('07_Raw_Balance_Sheet'!$C$5:$G$100,MATCH($A10,'07_Raw_Balance_Sheet'!$A$5:$A$100,0),MATCH(C$4,'07_Raw_Balance_Sheet'!$C$4:$G$4,0)),"") -> -6037 | D10: =IFERROR(INDEX('07_Raw_Balance_Sheet'!$C$5:$G$100,MATCH($A10,'07_Raw_Balance_Sheet'!$A$5:$A$100,0),MATCH(D$4,'07_Raw_Balance_Sheet'!$C$4:$G$4,0)),"") -> -7093 | E10: =IFERROR(INDEX('07_Raw_Balance_Sheet'!$C$5:$G$100,MATCH($A10,'07_Raw_Balance_Sheet'!$A$5:$A$100,0),MATCH(E$4,'07_Raw_Balance_Sheet'!$C$4:$G$4,0)),"") -> -7401 | F10: =IFERROR(INDEX('07_Raw_Balance_Sheet'!$C$5:$G$100,MATCH($A10,'07_Raw_Balance_Sheet'!$A$5:$A$100,0),MATCH(F$4,'07_Raw_Balance_Sheet'!$C$4:$G$4,0)),"") -> -7521
A11: Loans, Net of Allowance | B11: =IFERROR(INDEX('07_Raw_Balance_Sheet'!$C$5:$G$100,MATCH($A11,'07_Raw_Balance_Sheet'!$A$5:$A$100,0),MATCH(B$4,'07_Raw_Balance_Sheet'!$C$4:$G$4,0)),"") -> 852773 | C11: =IFERROR(INDEX('07_Raw_Balance_Sheet'!$C$5:$G$100,MATCH($A11,'07_Raw_Balance_Sheet'!$A$5:$A$100,0),MATCH(C$4,'07_Raw_Balance_Sheet'!$C$4:$G$4,0)),"") -> 981380 | D11: =IFERROR(INDEX('07_Raw_Balance_Sheet'!$C$5:$G$100,MATCH($A11,'07_Raw_Balance_Sheet'!$A$5:$A$100,0),MATCH(D$4,'07_Raw_Balance_Sheet'!$C$4:$G$4,0)),"") -> 1042422 | E11: =IFERROR(INDEX('07_Raw_Balance_Sheet'!$C$5:$G$100,MATCH($A11,'07_Raw_Balance_Sheet'!$A$5:$A$100,0),MATCH(E$4,'07_Raw_Balance_Sheet'!$C$4:$G$4,0)),"") -> 1054881 | F11: =IFERROR(INDEX('07_Raw_Balance_Sheet'!$C$5:$G$100,MATCH($A11,'07_Raw_Balance_Sheet'!$A$5:$A$100,0),MATCH(F$4,'07_Raw_Balance_Sheet'!$C$4:$G$4,0)),"") -> 1077949
A12: Residential Mortgages | B12: =IFERROR(INDEX('07_Raw_Balance_Sheet'!$C$5:$G$100,MATCH($A12,'07_Raw_Balance_Sheet'!$A$5:$A$100,0),MATCH(B$4,'07_Raw_Balance_Sheet'!$C$4:$G$4,0)),"") -> 434501 | C12: =IFERROR(INDEX('07_Raw_Balance_Sheet'!$C$5:$G$100,MATCH($A12,'07_Raw_Balance_Sheet'!$A$5:$A$100,0),MATCH(C$4,'07_Raw_Balance_Sheet'!$C$4:$G$4,0)),"") -> 477544 | D12: =IFERROR(INDEX('07_Raw_Balance_Sheet'!$C$5:$G$100,MATCH($A12,'07_Raw_Balance_Sheet'!$A$5:$A$100,0),MATCH(D$4,'07_Raw_Balance_Sheet'!$C$4:$G$4,0)),"") -> 493413 | E12: =IFERROR(INDEX('07_Raw_Balance_Sheet'!$C$5:$G$100,MATCH($A12,'07_Raw_Balance_Sheet'!$A$5:$A$100,0),MATCH(E$4,'07_Raw_Balance_Sheet'!$C$4:$G$4,0)),"") -> 496529 | F12: =IFERROR(INDEX('07_Raw_Balance_Sheet'!$C$5:$G$100,MATCH($A12,'07_Raw_Balance_Sheet'!$A$5:$A$100,0),MATCH(F$4,'07_Raw_Balance_Sheet'!$C$4:$G$4,0)),"") -> 500879
A13: Personal Loans | B13: =IFERROR(INDEX('07_Raw_Balance_Sheet'!$C$5:$G$100,MATCH($A13,'07_Raw_Balance_Sheet'!$A$5:$A$100,0),MATCH(B$4,'07_Raw_Balance_Sheet'!$C$4:$G$4,0)),"") -> 98734 | C13: =IFERROR(INDEX('07_Raw_Balance_Sheet'!$C$5:$G$100,MATCH($A13,'07_Raw_Balance_Sheet'!$A$5:$A$100,0),MATCH(C$4,'07_Raw_Balance_Sheet'!$C$4:$G$4,0)),"") -> 108338 | D13: =IFERROR(INDEX('07_Raw_Balance_Sheet'!$C$5:$G$100,MATCH($A13,'07_Raw_Balance_Sheet'!$A$5:$A$100,0),MATCH(D$4,'07_Raw_Balance_Sheet'!$C$4:$G$4,0)),"") -> 115345 | E13: =IFERROR(INDEX('07_Raw_Balance_Sheet'!$C$5:$G$100,MATCH($A13,'07_Raw_Balance_Sheet'!$A$5:$A$100,0),MATCH(E$4,'07_Raw_Balance_Sheet'!$C$4:$G$4,0)),"") -> 115489 | F13: =IFERROR(INDEX('07_Raw_Balance_Sheet'!$C$5:$G$100,MATCH($A13,'07_Raw_Balance_Sheet'!$A$5:$A$100,0),MATCH(F$4,'07_Raw_Balance_Sheet'!$C$4:$G$4,0)),"") -> 117720
A14: Credit Cards | B14: =IFERROR(INDEX('07_Raw_Balance_Sheet'!$C$5:$G$100,MATCH($A14,'07_Raw_Balance_Sheet'!$A$5:$A$100,0),MATCH(B$4,'07_Raw_Balance_Sheet'!$C$4:$G$4,0)),"") -> 23035 | C14: =IFERROR(INDEX('07_Raw_Balance_Sheet'!$C$5:$G$100,MATCH($A14,'07_Raw_Balance_Sheet'!$A$5:$A$100,0),MATCH(C$4,'07_Raw_Balance_Sheet'!$C$4:$G$4,0)),"") -> 25565 | D14: =IFERROR(INDEX('07_Raw_Balance_Sheet'!$C$5:$G$100,MATCH($A14,'07_Raw_Balance_Sheet'!$A$5:$A$100,0),MATCH(D$4,'07_Raw_Balance_Sheet'!$C$4:$G$4,0)),"") -> 26789 | E14: =IFERROR(INDEX('07_Raw_Balance_Sheet'!$C$5:$G$100,MATCH($A14,'07_Raw_Balance_Sheet'!$A$5:$A$100,0),MATCH(E$4,'07_Raw_Balance_Sheet'!$C$4:$G$4,0)),"") -> 26489 | F14: =IFERROR(INDEX('07_Raw_Balance_Sheet'!$C$5:$G$100,MATCH($A14,'07_Raw_Balance_Sheet'!$A$5:$A$100,0),MATCH(F$4,'07_Raw_Balance_Sheet'!$C$4:$G$4,0)),"") -> 27702
A15: Business and Government Loans | B15: =IFERROR(INDEX('07_Raw_Balance_Sheet'!$C$5:$G$100,MATCH($A15,'07_Raw_Balance_Sheet'!$A$5:$A$100,0),MATCH(B$4,'07_Raw_Balance_Sheet'!$C$4:$G$4,0)),"") -> 309571 | C15: =IFERROR(INDEX('07_Raw_Balance_Sheet'!$C$5:$G$100,MATCH($A15,'07_Raw_Balance_Sheet'!$A$5:$A$100,0),MATCH(C$4,'07_Raw_Balance_Sheet'!$C$4:$G$4,0)),"") -> 360474 | D15: =IFERROR(INDEX('07_Raw_Balance_Sheet'!$C$5:$G$100,MATCH($A15,'07_Raw_Balance_Sheet'!$A$5:$A$100,0),MATCH(D$4,'07_Raw_Balance_Sheet'!$C$4:$G$4,0)),"") -> 397190 | E15: =IFERROR(INDEX('07_Raw_Balance_Sheet'!$C$5:$G$100,MATCH($A15,'07_Raw_Balance_Sheet'!$A$5:$A$100,0),MATCH(E$4,'07_Raw_Balance_Sheet'!$C$4:$G$4,0)),"") -> 406864 | F15: =IFERROR(INDEX('07_Raw_Balance_Sheet'!$C$5:$G$100,MATCH($A15,'07_Raw_Balance_Sheet'!$A$5:$A$100,0),MATCH(F$4,'07_Raw_Balance_Sheet'!$C$4:$G$4,0)),"") -> 422154
A16: Other Assets | B16: =IFERROR(INDEX('07_Raw_Balance_Sheet'!$C$5:$G$100,MATCH($A16,'07_Raw_Balance_Sheet'!$A$5:$A$100,0),MATCH(B$4,'07_Raw_Balance_Sheet'!$C$4:$G$4,0)),"") -> 81371 | C16: =IFERROR(INDEX('07_Raw_Balance_Sheet'!$C$5:$G$100,MATCH($A16,'07_Raw_Balance_Sheet'!$A$5:$A$100,0),MATCH(C$4,'07_Raw_Balance_Sheet'!$C$4:$G$4,0)),"") -> 92190 | D16: =IFERROR(INDEX('07_Raw_Balance_Sheet'!$C$5:$G$100,MATCH($A16,'07_Raw_Balance_Sheet'!$A$5:$A$100,0),MATCH(D$4,'07_Raw_Balance_Sheet'!$C$4:$G$4,0)),"") -> 112893 | E16: =IFERROR(INDEX('07_Raw_Balance_Sheet'!$C$5:$G$100,MATCH($A16,'07_Raw_Balance_Sheet'!$A$5:$A$100,0),MATCH(E$4,'07_Raw_Balance_Sheet'!$C$4:$G$4,0)),"") -> 115296 | F16: =IFERROR(INDEX('07_Raw_Balance_Sheet'!$C$5:$G$100,MATCH($A16,'07_Raw_Balance_Sheet'!$A$5:$A$100,0),MATCH(F$4,'07_Raw_Balance_Sheet'!$C$4:$G$4,0)),"") -> 111841
... A25: Loans and Acceptances | B25: =IFERROR(INDEX('07_Raw_Balance_Sheet'!$C$5:$G$100,MATCH($A25,'07_Raw_Balance_Sheet'!$A$5:$A$100,0),MATCH(B$4,'07_Raw_Balance_Sheet'!$C$4:$G$4,0)),"") -> 879522 | C25: =IFERROR(INDEX('07_Raw_Balance_Sheet'!$C$5:$G$100,MATCH($A25,'07_Raw_Balance_Sheet'!$A$5:$A$100,0),MATCH(C$4,'07_Raw_Balance_Sheet'!$C$4:$G$4,0)),"") -> 987452 | D25: =IFERROR(INDEX('07_Raw_Balance_Sheet'!$C$5:$G$100,MATCH($A25,'07_Raw_Balance_Sheet'!$A$5:$A$100,0),MATCH(D$4,'07_Raw_Balance_Sheet'!$C$4:$G$4,0)),"") -> 1049534 | E25: =IFERROR(INDEX('07_Raw_Balance_Sheet'!$C$5:$G$100,MATCH($A25,'07_Raw_Balance_Sheet'!$A$5:$A$100,0),MATCH(E$4,'07_Raw_Balance_Sheet'!$C$4:$G$4,0)),"") -> 1062298 | F25: =IFERROR(INDEX('07_Raw_Balance_Sheet'!$C$5:$G$100,MATCH($A25,'07_Raw_Balance_Sheet'!$A$5:$A$100,0),MATCH(F$4,'07_Raw_Balance_Sheet'!$C$4:$G$4,0)),"") -> 1085510

Sheet 13_STD_Credit_Risk
A1: STANDARDIZED CREDIT RISK
A4: Metric | B4: FY2023 | C4: FY2024 | D4: FY2025 | E4: Q1 2026 | F4: Q2 2026
